Workbook

Sheet Overview
A1: Summary
A2: Topic | B2: Details
A3: Project | B3: LSC End of Coal Program - Apparel Sustainable Supply Chain
A4: Case | B4: TEXIN Factory Vietnam
A5: Key Outcome | B5: ~64% CO2 reduction after replacing 78% coal with biomass
A6: Strategic Impact | B6: Supplier decarbonization and ESG compliance
A7: Case 2A Challenge | B7: 5-year ESG CAPEX/OPEX phasing + P&L constraints, supported by 2026 actual volume and 2027-2029 potential-order scenarios
A9: LSC Strategy
A10: Area | B10: Requirement
A11: Carbon | B11: Measure and reduce emissions
A12: Energy | B12: Renewable energy and coal elimination
A13: Suppliers | B13: Decarbonization roadmap
A15: TEXIN SOP
A16: Fuel Receiving | B16: Rice husk pellets/wood pellets
A17: QC | B17: Moisture and particle-size inspection
A18: Storage | B18: Covered warehouse and fire prevention
A19: Fuel Feeding | B19: Automatic feeding system
A20: Combustion | B20: Air/fuel ratio control
A21: Steam Generation | B21: Boiler operation
A22: Production | B22: Steam consumption in manufacturing
A23: Ash Handling | B23: Reuse or disposal

Sheet Fuel comparison
A1: Metric | B1: Coal | C1: Rice Husk Pellet | D1: Wood Pellet
A2: NCV kcal/kg | B2: 6300-7000 | C2: 3800-4500 | D2: 4200-4800
A3: CO2 tCO2/t fuel | B3: 2.4-2.7 | C3: 0.15-0.30 | D3: 0.10-0.25
A4: Ash % | B4: 10-25 | C4: 8-15 | D4: 1-5
A5: Cost VNĐ/Tons | B5: 2.5-3.0M | C5: 1.8-3.0M | D5: 3.5-5.0M

Sheet CO2 Emission Calculation
A1: CO2 Emission Calculation - Fuel Comparison
A3: Fuel | B3: NCV (GJ/t) | C3: EF (kgCO2/GJ) | D3: Formula | E3: CO2 (kg/t fuel) | F3: CO2 (t/t fuel)
A4: Coal | B4: 25 | C4: 94.6 | D4: NCV × EF | E4: =B4*C4 -> 2365 | F4: =E4/1000 -> 2.365
A5: Rice Husk Pellet | B5: 16 | C5: 10 | D5: NCV × EF | E5: =B5*C5 -> 160 | F5: =E5/1000 -> 0.16
A6: Wood Pellet | B6: 18 | C6: 7 | D6: NCV × EF | E6: =B6*C6 -> 126 | F6: =E6/1000 -> 0.126
A8: Fuel comparison
A9: Metric | B9: Coal | C9: Rice husk pellet | D9: Wood pellet
A10: NCV kcal/kg | B10: 6,300 - 7,000 | C10: 3,800 - 4,500 | D10: 4,200 - 4,800
A11: CO2 tCO2/t fuel | B11: 2.4-2.7 | C11: 0.15-0.30 | D11: 0.10-0.25
A12: Ash % | B12: 10-25 | C12: 8-15 | D12: 1-5
A13: Cost VND/Tons | B13: 2.5-3.0M | C13: 1.8-3.0M | D13: 3.5-5.0M
A15: Carbon reduction
A16: Scenario | B16: Emission Index
A17: 100% Coal | B17: 100
A18: 78% Biomass + 22% Coal | B18: 36
A19: Reduction % | B19: 64
A21: Index | B21: Meaning
A22: NCV (Net Calorific Value) | B22: Useful heat energy generated by 1 ton of fuel. Higher NCV means less fuel is needed to produce the same heat.
A23: EF (Emission Factor) | B23: Amount of CO2 emitted per GJ of energy generated. For biomass, the EF shown here is life-cycle CO2e, mainly from collection, pelletizing, and transport.
A24: CO2 kg/t fuel | B24: CO2 emitted when burning or using 1 ton of fuel, calculated as NCV × EF.
A25: CO2 t/t fuel | B25: CO2 kg/t fuel divided by 1,000.
A27: Simple example | B27: Coal | C27: Rice husk pellet | D27: Wood pellet | E27: Note
A28: Fuel amount used (t/year) | B28: 1000 | C28: 1560 | D28: 1390 | E28: Biomass amount adjusted to generate similar heat as 1,000 t coal
A29: Total energy (GJ/year) | B29: =B28*B4 -> 25000 | C29: =C28*B5 -> 24960 | D29: =D28*B6 -> 25020 | E29: Fuel amount × NCV
A30: Total CO2 (tCO2e/year) | B30: =B28*F4 -> 2365 | C30: =C28*F5 -> 249.6 | D30: =D28*F6 -> 175.14 | E30: Fuel amount × CO2 t/t fuel
A31: CO2 reduction vs coal | B31: - | C31: =(B30-C30)/B30 -> 0.89446089 | D31: =(B30-D30)/B30 -> 0.92594503 | E31: Compared with coal baseline
A33: Key takeaway | B33: Coal has higher heat value, but also much higher emission factor.
A34: 1 | B34: Rice husk pellet and wood pellet require more tons of fuel for the same heat output.
A35: 2 | B35: However, their life-cycle CO2e is much lower, which is why coal-to-biomass conversion can significantly reduce Scope 1-related emissions.
A36: 3 | B36: In the TEXIN/LSC case, partial replacement of coal with biomass led to an estimated ~64% CO2 reduction.

Sheet Carbon-Allowed Capacity
B1: CARBON-ALLOWED CAPACITY 2027–2031 · supporting calculation for Task 2
B2: Reverse calculation from the buyer caps: CO2e = heat intensity × volume × emission factor ≤ cap, so maximum volume = cap × 1,000 ÷ (heat intensity × EF). Both caps are tested: absolute tCO2e and kgCO2e/GJ intensity.
B4: DESIGN BIOMASS MIX | C4: CAPACITY 2027 | E4: CAPACITY 2029 | G4: CAPACITY 2031 | J4: MIN. BIOMASS SHARE 2031 | L4: COAL-ONLY VOLUME 2031 | N4: PEAK HEAT AT CAPACITY
B5: =C21 -> 0.78 | C5: =D36 -> 9100807.2 | E5: =F36 -> 9358316 | G5: =H36 -> 6125443.2 | J5: =H28 -> 0.70811696 | L5: =H53 -> 1807200 | N5: =MAX(D38:H38) -> 2.3726263
B6: Emission Target F11 (~78% biomass) | C6: =TEXT(D27,"0%")&" of 2027 on biomass" -> 75% of 2027 on biomass | E6: ="vs potential orders "&TEXT(F48/1000000,"0.00")&"M" -> vs potential orders 9.80M | G6: Caps tighten faster than EF falls | J6: Below this, any volume fails | L6: Absolute cap on 100% coal | N6: × 2026 heat; no boiler rating in the case
B8: Inputs and method
B9: Parameter | C9: Value | D9: Unit | E9: Basis / source | J9: Reading the result
B10: 2026 useful heat demand | C10: ='ESG_CAPEX OPEX'!B6 -> 300000 | D10: GJ/yr | E10: ESG_CAPEX OPEX B6 (sized for dyeing/finishing steam demand). | J10: 1. The reverse calculation is valid only because heat is assumed to scale with volume. If heat were fixed at 300,000 GJ, CO2e would not depend on volume and no capacity could be derived from the caps.
B11: 2026 actual sales volume | C11: ='Sales Forecast & Case 2A KPI'!C21 -> 5020000 | D11: pcs | E11: Sales Forecast C21; produces the 28,380 t baseline (Emission Target J6).
B12: Heat intensity (held at 2026 level) | C12: =$C$10/$C$11 -> 0.059760956 | D12: GJ/pc | E12: Team assumption: heat moves in proportion to output (steam per kg of fabric dyed and finished). | J12: 2. Team decision: this envelope is adopted in Task 2 as the planning capacity. Sewing labour is variable and costed per piece through COGS, and the case gives no boiler rating, so the carbon budget is the only hard volume limit the case quantifies.
B13: Emission factor: coal | C13: ='CO2 Emission Calculation'!C4 -> 94.6 | D13: kgCO2e/GJ | E13: CO2 Emission Calculation C4.
B14: Emission factor: rice husk pellet | C14: ='CO2 Emission Calculation'!C5 -> 10 | D14: kgCO2e/GJ | E14: CO2 Emission Calculation C5 (life-cycle). | J14: 3. Against risk-adjusted demand (Task 2) the envelope does not bind in 2027–2029 and binds in 2030–2031. Against the full potential orders it would already bind in 2029.
B15: Emission factor: wood pellet | C15: ='CO2 Emission Calculation'!C6 -> 7 | D15: kgCO2e/GJ | E15: CO2 Emission Calculation C6 (life-cycle).
B16: Rice husk share of biomass heat | C16: ='ESG_CAPEX OPEX'!B10 -> 0.7 | D16: % of heat | E16: ESG_CAPEX OPEX B10 (base-case blend). | J16: 4. Capacity shrinks from 2028 to 2031 at a constant mix because the caps tighten faster than EF falls. Growth after 2029 needs a higher biomass share or heat-recovery savings (Emission Target F10).
B17: Wood pellet share of biomass heat | C17: ='ESG_CAPEX OPEX'!B11 -> 0.3 | D17: % of heat | E17: ESG_CAPEX OPEX B11.
B18: Emission factor: biomass blend | C18: =$C$16*$C$14+$C$17*$C$15 -> 9.1 | D18: kgCO2e/GJ | E18: Heat-weighted blend of the two pellets. | J18: 5. At the envelope CO2e equals the cap exactly. Task 1 therefore runs the boiler at the next 5% biomass step above the requirement, keeping CO2e at least 5% below the cap (R01, R02).
B19: Biomass firing starts (2027) | C19: ='Task 1_ESG Roadmap'!$C$117 -> 46478 | D19: date | E19: Linked to the Task 1 commissioning milestone (in service 1 Apr 2027).
B20: Share of 2027 with the biomass system in service | C20: =(DATE(2027,12,31)-$C$19+1)/365 -> 0.75342466 | D20: % of year | E20: Days in service ÷ 365. | J20: 6. Case consistency: with the case emission factors, 78% biomass gives a 70.5% reduction, not the ~64% quoted in Overview B5; a 64% cut on fixed heat needs about 70.8% biomass. This model uses the CO2 Emission Calculation factors throughout.
B21: Case target operating mix: biomass share | C21: 0.78 | D21: % of heat | E21: Emission Target F11 ('~78% biomass/22% coal equivalent performance'); Overview B5.
B23: Buyer caps and the minimum biomass share they imply
B24: Metric | C24: 2026 | D24: 2027 | E24: 2028 | F24: 2029 | G24: 2030 | H24: 2031
B25: Buyer cap: maximum annual CO2e (t) | C25: ='Emission Target'!D6 -> 28380 | D25: ='Emission Target'!D7 -> 24123 | E25: ='Emission Target'!D8 -> 19866 | F25: ='Emission Target'!D9 -> 15609 | G25: ='Emission Target'!D10 -> 12771 | H25: ='Emission Target'!D11 -> 10216.8
B26: Buyer cap: maximum CO2e intensity (kg/GJ) | C26: ='Emission Target'!E6 -> 94.6 | D26: ='Emission Target'!E7 -> 80.41 | E26: ='Emission Target'!E8 -> 66.22 | F26: ='Emission Target'!E9 -> 52.03 | G26: ='Emission Target'!E10 -> 42.57 | H26: ='Emission Target'!E11 -> 34.056
B27: Share of year biomass system in service | C27: 0 | D27: =$C$20 -> 0.75342466 | E27: 1 | F27: 1 | G27: 1 | H27: 1
B28: Minimum biomass share while in service (intensity cap) | C28: n/a | D28: =MAX(0,($C$13-D26)/($C$13-$C$18)/D27) -> 0.2202807 | E28: =MAX(0,($C$13-E26)/($C$13-$C$18)/E27) -> 0.33192982 | F28: =MAX(0,($C$13-F26)/($C$13-$C$18)/F27) -> 0.49789474 | G28: =MAX(0,($C$13-G26)/($C$13-$C$18)/G27) -> 0.60853801 | H28: =MAX(0,($C$13-H26)/($C$13-$C$18)/H27) -> 0.70811696
B30: Carbon-allowed capacity at the case design mix
B31: Metric | C31: 2026 | D31: 2027 | E31: 2028 | F31: 2029 | G31: 2030 | H31: 2031
B32: Operating biomass share while in service | C32: 0 | D32: =$C$21 -> 0.78 | E32: =$C$21 -> 0.78 | F32: =$C$21 -> 0.78 | G32: =$C$21 -> 0.78 | H32: =$C$21 -> 0.78
B33: Annual average biomass share of heat | C33: =C32*C27 -> 0 | D33: =D32*D27 -> 0.58767123 | E33: =E32*E27 -> 0.78 | F33: =F32*F27 -> 0.78 | G33: =G32*G27 -> 0.78 | H33: =H32*H27 -> 0.78
B34: Annual average emission factor (kg/GJ) | C34: =$C$13-C33*($C$13-$C$18) -> 94.6 | D34: =$C$13-D33*($C$13-$C$18) -> 44.35411 | E34: =$C$13-E33*($C$13-$C$18) -> 27.91 | F34: =$C$13-F33*($C$13-$C$18) -> 27.91 | G34: =$C$13-G33*($C$13-$C$18) -> 27.91 | H34: =$C$13-H33*($C$13-$C$18) -> 27.91
B35: Intensity cap met? | C35: =IF(C34<=C26+0.000001,"Yes","No") -> Yes | D35: =IF(D34<=D26+0.000001,"Yes","No") -> Yes | E35: =IF(E34<=E26+0.000001,"Yes","No") -> Yes | F35: =IF(F34<=F26+0.000001,"Yes","No") -> Yes | G35: =IF(G34<=G26+0.000001,"Yes","No") -> Yes | H35: =IF(H34<=H26+0.000001,"Yes","No") -> Yes
B36: Carbon-allowed capacity (pcs) | C36: =IF(C35="Yes",C25*1000/($C$12*C34),0) -> 5020000 | D36: =IF(D35="Yes",D25*1000/($C$12*D34),0) -> 9100807.2 | E36: =IF(E35="Yes",E25*1000/($C$12*E34),0) -> 11910584 | F36: =IF(F35="Yes",F25*1000/($C$12*F34),0) -> 9358316 | G36: =IF(G35="Yes",G25*1000/($C$12*G34),0) -> 7656804 | H36: =IF(H35="Yes",H25*1000/($C$12*H34),0) -> 6125443.2
B37: Heat required at this volume (GJ) | C37: =C36*$C$12 -> 300000 | D37: =D36*$C$12 -> 543872.94 | E37: =E36*$C$12 -> 711787.89 | F37: =F36*$C$12 -> 559261.91 | G37: =G36*$C$12 -> 457577.93 | H37: =H36*$C$12 -> 366062.34
B38: Heat required vs 2026 heat demand (×) | C38: =C37/$C$10 -> 1 | D38: =D37/$C$10 -> 1.8129098 | E38: =E37/$C$10 -> 2.3726263 | F38: =F37/$C$10 -> 1.8642064 | G38: =G37/$C$10 -> 1.5252598 | H38: =H37/$C$10 -> 1.2202078
B39: CO2e at this volume (t), check | C39: =C37*C34/1000 -> 28380 | D39: =D37*D34/1000 -> 24123 | E39: =E37*E34/1000 -> 19866 | F39: =F37*F34/1000 -> 15609 | G39: =G37*G34/1000 -> 12771 | H39: =H37*H34/1000 -> 10216.8
B40: Check: CO2e within the absolute and intensity caps | C40: =IF(AND(C39<=C25+0.5,C35="Yes"),"OK","Check") -> OK | D40: =IF(AND(D39<=D25+0.5,D35="Yes"),"OK","Check") -> OK | E40: =IF(AND(E39<=E25+0.5,E35="Yes"),"OK","Check") -> OK | F40: =IF(AND(F39<=F25+0.5,F35="Yes"),"OK","Check") -> OK | G40: =IF(AND(G39<=G25+0.5,G35="Yes"),"OK","Check") -> OK | H40: =IF(AND(H39<=H25+0.5,H35="Yes"),"OK","Check") -> OK
B46: Comparison with the case volumes
B47: Metric | C47: 2026 | D47: 2027 | E47: 2028 | F47: 2029 | G47: 2030 | H47: 2031
B48: ESG scenario: potential orders (pcs) | C48: ='Sales Forecast & Case 2A KPI'!C21 -> 5020000 | D48: ='Sales Forecast & Case 2A KPI'!D21 -> 6124400 | E48: ='Sales Forecast & Case 2A KPI'!E21 -> 7655500 | F48: ='Sales Forecast & Case 2A KPI'!F21 -> 9799040 | G48: n/a | H48: n/a
B49: Carbon-allowed capacity − potential orders (pcs) | C49: =C36-C48 -> 0 | D49: =D36-D48 -> 2976407.2 | E49: =E36-E48 -> 4255084 | F49: =F36-F48 -> -440723.98 | G49: n/a | H49: n/a
...

Sheet Task 1_ESG Roadmap
B1: TASK 1 - ESG ROAD MAP
B2: Requirement 1: five-year roadmap with CAPEX tranches, commissioning milestones, cumulative ESG completion and straight-line depreciation (5 years from the commissioning year, no salvage). Inputs in blue on cream, links to other sheets in green, formulas in black.
B4: TOTAL CAPEX ENVELOPE | C4: TRANCHE 1 · 2027 | E4: BIOMASS FIRING FROM | G4: ESG COMPLETION END-2027 | I4: CO2e CUT BY 2031 | K4: BUYER CAPS MET | M4: DEPRECIATION, FULL YEAR
B5: =C107 -> 940500 | C5: =C89 -> 896500 | E5: =C117 -> 46478 | G5: =D95 -> 0.95321637 | I5: =H77 -> 0.66205661 | K5: =COUNTIF(D78:H78,"Compliant")&" / 5 years" -> 5 / 5 years | M5: =E94 -> 188100
B6: Incl. 10% contingency; full scope kept | C6: =TEXT(C89/C107,"0.0%")&" of the envelope" -> 95.3% of the envelope | E6: Boiler tie-in in the LNY 2027 shutdown | G6: =TEXT(E95,"0%")&" from 2028 (Tranche 2)" -> 100% from 2028 (Tranche 2) | I6: ="Target "&TEXT('Emission Target'!C11,"0%")&"; index "&TEXT(H76,"0.0") -> Target 64%; index 33.8 | K6: ="Lowest headroom "&TEXT(MIN(D75:H75),"0.0%") -> Lowest headroom 6.1% | M6: 5-year straight line, no salvage
B8: Investment roadmap: CAPEX tranches, commissioning milestones and spend by year (USD)
B9: CAPEX item | C9: Priority | D9: Base cost | E9: Incl. 10% contingency | F9: Works start | G9: In service (milestone) | H9: Tranche | I9: 2027 | J9: 2028 | K9: 2029 | L9: 2030 | M9: 2031 | N9: Why this timing
B10: ='ESG_CAPEX OPEX'!A17 -> Biomass boiler/furnace retrofit package | C10: ='ESG_CAPEX OPEX'!H17 -> Critical | D10: ='ESG_CAPEX OPEX'!E17 -> 280000 | E10: =D10*(1+$C$108) -> 308000 | F10: 46388 | G10: 46478 | H10: ="T"&(YEAR(G10)-2026)&" ("&YEAR(G10)&")" -> T1 (2027) | I10: =IF(YEAR($G10)=2027,$E10,0) -> 308000 | J10: =IF(YEAR($G10)=2028,$E10,0) -> 0 | K10: =IF(YEAR($G10)=2029,$E10,0) -> 0 | L10: =IF(YEAR($G10)=2030,$E10,0) -> 0 | M10: =IF(YEAR($G10)=2031,$E10,0) -> 0 | N10: Critical. Core of conversion; tie-in during LNY 2027 shutdown. Needed to fire biomass at scale from Q2 2027 and meet the 2027 absolute cap.
B11: ='ESG_CAPEX OPEX'!A18 -> Fuel receiving, conveyor & automatic feeding | C11: ='ESG_CAPEX OPEX'!H18 -> Critical | D11: ='ESG_CAPEX OPEX'!E18 -> 120000 | E11: =D11*(1+$C$108) -> 132000 | F11: 46327 | G11: 46478 | H11: ="T"&(YEAR(G11)-2026)&" ("&YEAR(G11)&")" -> T1 (2027) | I11: =IF(YEAR($G11)=2027,$E11,0) -> 132000 | J11: =IF(YEAR($G11)=2028,$E11,0) -> 0 | K11: =IF(YEAR($G11)=2029,$E11,0) -> 0 | L11: =IF(YEAR($G11)=2030,$E11,0) -> 0 | M11: =IF(YEAR($G11)=2031,$E11,0) -> 0 | N11: Critical. Automatic feeding required before biomass firing; reduces manual handling (R05 dust/fire).
B12: ='ESG_CAPEX OPEX'!A19 -> Covered biomass warehouse & day silo | C12: ='ESG_CAPEX OPEX'!H19 -> Critical | D12: ='ESG_CAPEX OPEX'!E19 -> 85000 | E12: =D12*(1+$C$108) -> 93500 | F12: 46296 | G12: 46447 | H12: ="T"&(YEAR(G12)-2026)&" ("&YEAR(G12)&")" -> T1 (2027) | I12: =IF(YEAR($G12)=2027,$E12,0) -> 93500 | J12: =IF(YEAR($G12)=2028,$E12,0) -> 0 | K12: =IF(YEAR($G12)=2029,$E12,0) -> 0 | L12: =IF(YEAR($G12)=2030,$E12,0) -> 0 | M12: =IF(YEAR($G12)=2031,$E12,0) -> 0 | N12: Critical. 10–14 day covered buffer must be stocked before firing; protects moisture spec (R02) and rainy-season supply (R01).
B13: ='ESG_CAPEX OPEX'!A20 -> Ash extraction & handling system | C13: ='ESG_CAPEX OPEX'!H20 -> High | D13: ='ESG_CAPEX OPEX'!E20 -> 45000 | E13: =D13*(1+$C$108) -> 49500 | F13: 46388 | G13: 46478 | H13: ="T"&(YEAR(G13)-2026)&" ("&YEAR(G13)&")" -> T1 (2027) | I13: =IF(YEAR($G13)=2027,$E13,0) -> 49500 | J13: =IF(YEAR($G13)=2028,$E13,0) -> 0 | K13: =IF(YEAR($G13)=2029,$E13,0) -> 0 | L13: =IF(YEAR($G13)=2030,$E13,0) -> 0 | M13: =IF(YEAR($G13)=2031,$E13,0) -> 0 | N13: High. Silica-rich rice-husk ash needs dedicated handling from first firing (R04 fouling).
B14: ='ESG_CAPEX OPEX'!A21 -> Multi-cyclone + bag filter upgrade | C14: ='ESG_CAPEX OPEX'!H21 -> Critical | D14: ='ESG_CAPEX OPEX'!E21 -> 95000 | E14: =D14*(1+$C$108) -> 104500 | F14: 46388 | G14: 46478 | H14: ="T"&(YEAR(G14)-2026)&" ("&YEAR(G14)&")" -> T1 (2027) | I14: =IF(YEAR($G14)=2027,$E14,0) -> 104500 | J14: =IF(YEAR($G14)=2028,$E14,0) -> 0 | K14: =IF(YEAR($G14)=2029,$E14,0) -> 0 | L14: =IF(YEAR($G14)=2030,$E14,0) -> 0 | M14: =IF(YEAR($G14)=2031,$E14,0) -> 0 | N14: Critical. Particulate control is a legal precondition for biomass combustion.
B15: ='ESG_CAPEX OPEX'!A22 -> Stack emission & energy metering system | C15: ='ESG_CAPEX OPEX'!H22 -> High | D15: ='ESG_CAPEX OPEX'!E22 -> 35000 | E15: =D15*(1+$C$108) -> 38500 | F15: 46296 | G15: 46388 | H15: ="T"&(YEAR(G15)-2026)&" ("&YEAR(G15)&")" -> T1 (2027) | I15: =IF(YEAR($G15)=2027,$E15,0) -> 38500 | J15: =IF(YEAR($G15)=2028,$E15,0) -> 0 | K15: =IF(YEAR($G15)=2029,$E15,0) -> 0 | L15: =IF(YEAR($G15)=2030,$E15,0) -> 0 | M15: =IF(YEAR($G15)=2031,$E15,0) -> 0 | N15: High. Metering first: verified 2026–2027 baseline and auditable annual CO2e (Emission Target F7, B19).
B16: ='ESG_CAPEX OPEX'!A23 -> Water treatment & condensate recovery upgrade | C16: ='ESG_CAPEX OPEX'!H23 -> Medium | D16: ='ESG_CAPEX OPEX'!E23 -> 40000 | E16: =D16*(1+$C$108) -> 44000 | F16: 46661 | G16: 46813 | H16: ="T"&(YEAR(G16)-2026)&" ("&YEAR(G16)&")" -> T2 (2028) | I16: =IF(YEAR($G16)=2027,$E16,0) -> 0 | J16: =IF(YEAR($G16)=2028,$E16,0) -> 44000 | K16: =IF(YEAR($G16)=2029,$E16,0) -> 0 | L16: =IF(YEAR($G16)=2030,$E16,0) -> 0 | M16: =IF(YEAR($G16)=2031,$E16,0) -> 0 | N16: Medium. Efficiency upgrade; installed after the main system stabilises, during LNY 2028. Savings not counted (conservative).
B17: ='ESG_CAPEX OPEX'!A24 -> Fire detection, dust control & safety system | C17: ='ESG_CAPEX OPEX'!H24 -> Critical | D17: ='ESG_CAPEX OPEX'!E24 -> 30000 | E17: =D17*(1+$C$108) -> 33000 | F17: 46327 | G17: 46447 | H17: ="T"&(YEAR(G17)-2026)&" ("&YEAR(G17)&")" -> T1 (2027) | I17: =IF(YEAR($G17)=2027,$E17,0) -> 33000 | J17: =IF(YEAR($G17)=2028,$E17,0) -> 0 | K17: =IF(YEAR($G17)=2029,$E17,0) -> 0 | L17: =IF(YEAR($G17)=2030,$E17,0) -> 0 | M17: =IF(YEAR($G17)=2031,$E17,0) -> 0 | N17: Critical. Must be live before biomass is stored on site (R05).
B18: ='ESG_CAPEX OPEX'!A25 -> Civil, electrical & piping modification | C18: ='ESG_CAPEX OPEX'!H25 -> High | D18: ='ESG_CAPEX OPEX'!E25 -> 55000 | E18: =D18*(1+$C$108) -> 60500 | F18: 46296 | G18: 46447 | H18: ="T"&(YEAR(G18)-2026)&" ("&YEAR(G18)&")" -> T1 (2027) | I18: =IF(YEAR($G18)=2027,$E18,0) -> 60500 | J18: =IF(YEAR($G18)=2028,$E18,0) -> 0 | K18: =IF(YEAR($G18)=2029,$E18,0) -> 0 | L18: =IF(YEAR($G18)=2030,$E18,0) -> 0 | M18: =IF(YEAR($G18)=2031,$E18,0) -> 0 | N18: High. Foundations, piping, MCC needed to integrate the retrofit.
B19: ='ESG_CAPEX OPEX'!A26 -> Engineering, commissioning & performance test | C19: ='ESG_CAPEX OPEX'!H26 -> High | D19: ='ESG_CAPEX OPEX'!E26 -> 45000 | E19: =D19*(1+$C$108) -> 49500 | F19: 46296 | G19: 46478 | H19: ="T"&(YEAR(G19)-2026)&" ("&YEAR(G19)&")" -> T1 (2027) | I19: =IF(YEAR($G19)=2027,$E19,0) -> 49500 | J19: =IF(YEAR($G19)=2028,$E19,0) -> 0 | K19: =IF(YEAR($G19)=2029,$E19,0) -> 0 | L19: =IF(YEAR($G19)=2030,$E19,0) -> 0 | M19: =IF(YEAR($G19)=2031,$E19,0) -> 0 | N19: High. Performance test is the formal commissioning gate of Tranche 1.
B20: ='ESG_CAPEX OPEX'!A27 -> ESG certification/traceability setup | C20: ='ESG_CAPEX OPEX'!H27 -> Medium | D20: ='ESG_CAPEX OPEX'!E27 -> 25000 | E20: =D20*(1+$C$108) -> 27500 | F20: 46327 | G20: 46419 | H20: ="T"&(YEAR(G20)-2026)&" ("&YEAR(G20)&")" -> T1 (2027) | I20: =IF(YEAR($G20)=2027,$E20,0) -> 27500 | J20: =IF(YEAR($G20)=2028,$E20,0) -> 0 | K20: =IF(YEAR($G20)=2029,$E20,0) -> 0 | L20: =IF(YEAR($G20)=2030,$E20,0) -> 0 | M20: =IF(YEAR($G20)=2031,$E20,0) -> 0 | N20: Medium in case data, but needed before the first biomass purchase to avoid greenwashing claims (R06).
B21: CAPEX spend in year | D21: =SUM(D10:D20) -> 855000 | E21: =SUM(E10:E20) -> 940500 | I21: =SUM(I10:I20) -> 896500 | J21: =SUM(J10:J20) -> 44000 | K21: =SUM(K10:K20) -> 0 | L21: =SUM(L10:L20) -> 0 | M21: =SUM(M10:M20) -> 0 | N21: Spend is booked in the tranche (commissioning) year, as in the case template row 47.
B22: Cumulative CAPEX in service | I22: =I21 -> 896500 | J22: =J21+I22 -> 940500 | K22: =K21+J22 -> 940500 | L22: =L21+K22 -> 940500 | M22: =M21+L22 -> 940500 | N22: ESG completion = CAPEX value in service ÷ envelope (USD 940,500). A tranche counts only from its in-service date: a CAPEX commitment alone earns no credit (Emission Target F18).
B23: Cumulative ESG completion (% of the CAPEX envelope) | I23: =I22/$C$107 -> 0.95321637 | J23: =J22/$C$107 -> 1 | K23: =K22/$C$107 -> 1 | L23: =L22/$C$107 -> 1 | M23: =M22/$C$107 -> 1
B24: Check: tranche total = CAPEX envelope | E24: =IF(ABS(E21-C107)<1,"OK","CHECK") -> OK
B26: Commissioning Gantt by quarter, Q4 2026 to Q2 2029 (bars follow the dates in the roadmap table)
B27: Year | C27: 2026 | D27: 2027 | H27: 2028 | L27: 2029 | N27: Works window → in service | O27: Start | P27: In service / end
B28: CAPEX item / milestone | C28: Q4 2026 | D28: Q1 2027 | E28: Q2 2027 | F28: Q3 2027 | G28: Q4 2027 | H28: Q1 2028 | I28: Q2 2028 | J28: Q3 2028 | K28: Q4 2028 | L28: Q1 2029 | M28: Q2 2029
B29: Tranche 1 (2027): biomass conversion core, 10 items | C29: =IF(AND($P29>=DATE(2026,10,1),$P29<DATE(2026,13,1)),DAY($P29)&" "&CHOOSE(MONTH($P29),"Jan","Feb","Mar","Apr","May","Jun","Jul","Aug","Sep","Oct","Nov","Dec"),"") | D29: =IF(AND($P29>=DATE(2027,1,1),$P29<DATE(2027,4,1)),DAY($P29)&" "&CHOOSE(MONTH($P29),"Jan","Feb","Mar","Apr","May","Jun","Jul","Aug","Sep","Oct","Nov","Dec"),"") | E29: =IF(AND($P29>=DATE(2027,4,1),$P29<DATE(2027,7,1)),DAY($P29)&" "&CHOOSE(MONTH($P29),"Jan","Feb","Mar","Apr","May","Jun","Jul","Aug","Sep","Oct","Nov","Dec"),"") -> 1 Apr | F29: =IF(AND($P29>=DATE(2027,7,1),$P29<DATE(2027,10,1)),DAY($P29)&" "&CHOOSE(MONTH($P29),"Jan","Feb","Mar","Apr","May","Jun","Jul","Aug","Sep","Oct","Nov","Dec"),"") | G29: =IF(AND($P29>=DATE(2027,10,1),$P29<DATE(2027,13,1)),DAY($P29)&" "&CHOOSE(MONTH($P29),"Jan","Feb","Mar","Apr","May","Jun","Jul","Aug","Sep","Oct","Nov","Dec"),"") | H29: =IF(AND($P29>=DATE(2028,1,1),$P29<DATE(2028,4,1)),DAY($P29)&" "&CHOOSE(MONTH($P29),"Jan","Feb","Mar","Apr","May","Jun","Jul","Aug","Sep","Oct","Nov","Dec"),"") | I29: =IF(AND($P29>=DATE(2028,4,1),$P29<DATE(2028,7,1)),DAY($P29)&" "&CHOOSE(MONTH($P29),"Jan","Feb","Mar","Apr","May","Jun","Jul","Aug","Sep","Oct","Nov","Dec"),"") | J29: =IF(AND($P29>=DATE(2028,7,1),$P29<DATE(2028,10,1)),DAY($P29)&" "&CHOOSE(MONTH($P29),"Jan","Feb","Mar","Apr","May","Jun","Jul","Aug","Sep","Oct","Nov","Dec"),"") | K29: =IF(AND($P29>=DATE(2028,10,1),$P29<DATE(2028,13,1)),DAY($P29)&" "&CHOOSE(MONTH($P29),"Jan","Feb","Mar","Apr","May","Jun","Jul","Aug","Sep","Oct","Nov","Dec"),"") | L29: =IF(AND($P29>=DATE(2029,1,1),$P29<DATE(2029,4,1)),DAY($P29)&" "&CHOOSE(MONTH($P29),"Jan","Feb","Mar","Apr","May","Jun","Jul","Aug","Sep","Oct","Nov","Dec"),"") | M29: =IF(AND($P29>=DATE(2029,4,1),$P29<DATE(2029,7,1)),DAY($P29)&" "&CHOOSE(MONTH($P29),"Jan","Feb","Mar","Apr","May","Jun","Jul","Aug","Sep","Oct","Nov","Dec"),"") | N29: =CHOOSE(MONTH(O29),"Jan","Feb","Mar","Apr","May","Jun","Jul","Aug","Sep","Oct","Nov","Dec")&" "&YEAR(O29)&" → "&DAY(P29)&" "&CHOOSE(MONTH(P29),"Jan","Feb","Mar","Apr","May","Jun","Jul","Aug","Sep","Oct","Nov","Dec")&" "&YEAR(P29)&" ("&((YEAR(P29)-YEAR(O29))*12+MONTH(P29)-MONTH(O29))&" months)" -> Oct 2026 → 1 Apr 2027 (6 months) | O29: =MIN(F15,F12,F18,F19,F11,F17,F20,F10,F13,F14) -> 46296 | P29: =MAX(G15,G12,G18,G19,G11,G17,G20,G10,G13,G14) -> 46478
B30: =B15 -> Stack emission & energy metering system | C30: =IF(AND($P30>=DATE(2026,10,1),$P30<DATE(2026,13,1)),DAY($P30)&" "&CHOOSE(MONTH($P30),"Jan","Feb","Mar","Apr","May","Jun","Jul","Aug","Sep","Oct","Nov","Dec"),"") | D30: =IF(AND($P30>=DATE(2027,1,1),$P30<DATE(2027,4,1)),DAY($P30)&" "&CHOOSE(MONTH($P30),"Jan","Feb","Mar","Apr","May","Jun","Jul","Aug","Sep","Oct","Nov","Dec"),"") -> 1 Jan | E30: =IF(AND($P30>=DATE(2027,4,1),$P30<DATE(2027,7,1)),DAY($P30)&" "&CHOOSE(MONTH($P30),"Jan","Feb","Mar","Apr","May","Jun","Jul","Aug","Sep","Oct","Nov","Dec"),"") | F30: =IF(AND($P30>=DATE(2027,7,1),$P30<DATE(2027,10,1)),DAY($P30)&" "&CHOOSE(MONTH($P30),"Jan","Feb","Mar","Apr","May","Jun","Jul","Aug","Sep","Oct","Nov","Dec"),"") | G30: =IF(AND($P30>=DATE(2027,10,1),$P30<DATE(2027,13,1)),DAY($P30)&" "&CHOOSE(MONTH($P30),"Jan","Feb","Mar","Apr","May","Jun","Jul","Aug","Sep","Oct","Nov","Dec"),"") | H30: =IF(AND($P30>=DATE(2028,1,1),$P30<DATE(2028,4,1)),DAY($P30)&" "&CHOOSE(MONTH($P30),"Jan","Feb","Mar","Apr","May","Jun","Jul","Aug","Sep","Oct","Nov","Dec"),"") | I30: =IF(AND($P30>=DATE(2028,4,1),$P30<DATE(2028,7,1)),DAY($P30)&" "&CHOOSE(MONTH($P30),"Jan","Feb","Mar","Apr","May","Jun","Jul","Aug","Sep","Oct","Nov","Dec"),"") | J30: =IF(AND($P30>=DATE(2028,7,1),$P30<DATE(2028,10,1)),DAY($P30)&" "&CHOOSE(MONTH($P30),"Jan","Feb","Mar","Apr","May","Jun","Jul","Aug","Sep","Oct","Nov","Dec"),"") | K30: =IF(AND($P30>=DATE(2028,10,1),$P30<DATE(2028,13,1)),DAY($P30)&" "&CHOOSE(MONTH($P30),"Jan","Feb","Mar","Apr","May","Jun","Jul","Aug","Sep","Oct","Nov","Dec"),"") | L30: =IF(AND($P30>=DATE(2029,1,1),$P30<DATE(2029,4,1)),DAY($P30)&" "&CHOOSE(MONTH($P30),"Jan","Feb","Mar","Apr","May","Jun","Jul","Aug","Sep","Oct","Nov","Dec"),"") | M30: =IF(AND($P30>=DATE(2029,4,1),$P30<DATE(2029,7,1)),DAY($P30)&" "&CHOOSE(MONTH($P30),"Jan","Feb","Mar","Apr","May","Jun","Jul","Aug","Sep","Oct","Nov","Dec"),"") | N30: =CHOOSE(MONTH(O30),"Jan","Feb","Mar","Apr","May","Jun","Jul","Aug","Sep","Oct","Nov","Dec")&" "&YEAR(O30)&" → "&DAY(P30)&" "&CHOOSE(MONTH(P30),"Jan","Feb","Mar","Apr","May","Jun","Jul","Aug","Sep","Oct","Nov","Dec")&" "&YEAR(P30)&" ("&((YEAR(P30)-YEAR(O30))*12+MONTH(P30)-MONTH(O30))&" months)" -> Oct 2026 → 1 Jan 2027 (3 months) | O30: =F15 -> 46296 | P30: =G15 -> 46388
B31: =B12 -> Covered biomass warehouse & day silo | C31: =IF(AND($P31>=DATE(2026,10,1),$P31<DATE(2026,13,1)),DAY($P31)&" "&CHOOSE(MONTH($P31),"Jan","Feb","Mar","Apr","May","Jun","Jul","Aug","Sep","Oct","Nov","Dec"),"") | D31: =IF(AND($P31>=DATE(2027,1,1),$P31<DATE(2027,4,1)),DAY($P31)&" "&CHOOSE(MONTH($P31),"Jan","Feb","Mar","Apr","May","Jun","Jul","Aug","Sep","Oct","Nov","Dec"),"") -> 1 Mar | E31: =IF(AND($P31>=DATE(2027,4,1),$P31<DATE(2027,7,1)),DAY($P31)&" "&CHOOSE(MONTH($P31),"Jan","Feb","Mar","Apr","May","Jun","Jul","Aug","Sep","Oct","Nov","Dec"),"") | F31: =IF(AND($P31>=DATE(2027,7,1),$P31<DATE(2027,10,1)),DAY($P31)&" "&CHOOSE(MONTH($P31),"Jan","Feb","Mar","Apr","May","Jun","Jul","Aug","Sep","Oct","Nov","Dec"),"") | G31: =IF(AND($P31>=DATE(2027,10,1),$P31<DATE(2027,13,1)),DAY($P31)&" "&CHOOSE(MONTH($P31),"Jan","Feb","Mar","Apr","May","Jun","Jul","Aug","Sep","Oct","Nov","Dec"),"") | H31: =IF(AND($P31>=DATE(2028,1,1),$P31<DATE(2028,4,1)),DAY($P31)&" "&CHOOSE(MONTH($P31),"Jan","Feb","Mar","Apr","May","Jun","Jul","Aug","Sep","Oct","Nov","Dec"),"") | I31: =IF(AND($P31>=DATE(2028,4,1),$P31<DATE(2028,7,1)),DAY($P31)&" "&CHOOSE(MONTH($P31),"Jan","Feb","Mar","Apr","May","Jun","Jul","Aug","Sep","Oct","Nov","Dec"),"") | J31: =IF(AND($P31>=DATE(2028,7,1),$P31<DATE(2028,10,1)),DAY($P31)&" "&CHOOSE(MONTH($P31),"Jan","Feb","Mar","Apr","May","Jun","Jul","Aug","Sep","Oct","Nov","Dec"),"") | K31: =IF(AND($P31>=DATE(2028,10,1),$P31<DATE(2028,13,1)),DAY($P31)&" "&CHOOSE(MONTH($P31),"Jan","Feb","Mar","Apr","May","Jun","Jul","Aug","Sep","Oct","Nov","Dec"),"") | L31: =IF(AND($P31>=DATE(2029,1,1),$P31<DATE(2029,4,1)),DAY($P31)&" "&CHOOSE(MONTH($P31),"Jan","Feb","Mar","Apr","May","Jun","Jul","Aug","Sep","Oct","Nov","Dec"),"") | M31: =IF(AND($P31>=DATE(2029,4,1),$P31<DATE(2029,7,1)),DAY($P31)&" "&CHOOSE(MONTH($P31),"Jan","Feb","Mar","Apr","May","Jun","Jul","Aug","Sep","Oct","Nov","Dec"),"") | N31: =CHOOSE(MONTH(O31),"Jan","Feb","Mar","Apr","May","Jun","Jul","Aug","Sep","Oct","Nov","Dec")&" "&YEAR(O31)&" → "&DAY(P31)&" "&CHOOSE(MONTH(P31),"Jan","Feb","Mar","Apr","May","Jun","Jul","Aug","Sep","Oct","Nov","Dec")&" "&YEAR(P31)&" ("&((YEAR(P31)-YEAR(O31))*12+MONTH(P31)-MONTH(O31))&" months)" -> Oct 2026 → 1 Mar 2027 (5 months) | O31: =F12 -> 46296 | P31: =G12 -> 46447
B32: =B18 -> Civil, electrical & piping modification | C32: =IF(AND($P32>=DATE(2026,10,1),$P32<DATE(2026,13,1)),DAY($P32)&" "&CHOOSE(MONTH($P32),"Jan","Feb","Mar","Apr","May","Jun","Jul","Aug","Sep","Oct","Nov","Dec"),"") | D32: =IF(AND($P32>=DATE(2027,1,1),$P32<DATE(2027,4,1)),DAY($P32)&" "&CHOOSE(MONTH($P32),"Jan","Feb","Mar","Apr","May","Jun","Jul","Aug","Sep","Oct","Nov","Dec"),"") -> 1 Mar | E32: =IF(AND($P32>=DATE(2027,4,1),$P32<DATE(2027,7,1)),DAY($P32)&" "&CHOOSE(MONTH($P32),"Jan","Feb","Mar","Apr","May","Jun","Jul","Aug","Sep","Oct","Nov","Dec"),"") | F32: =IF(AND($P32>=DATE(2027,7,1),$P32<DATE(2027,10,1)),DAY($P32)&" "&CHOOSE(MONTH($P32),"Jan","Feb","Mar","Apr","May","Jun","Jul","Aug","Sep","Oct","Nov","Dec"),"") | G32: =IF(AND($P32>=DATE(2027,10,1),$P32<DATE(2027,13,1)),DAY($P32)&" "&CHOOSE(MONTH($P32),"Jan","Feb","Mar","Apr","May","Jun","Jul","Aug","Sep","Oct","Nov","Dec"),"") | H32: =IF(AND($P32>=DATE(2028,1,1),$P32<DATE(2028,4,1)),DAY($P32)&" "&CHOOSE(MONTH($P32),"Jan","Feb","Mar","Apr","May","Jun","Jul","Aug","Sep","Oct","Nov","Dec"),"") | I32: =IF(AND($P32>=DATE(2028,4,1),$P32<DATE(2028,7,1)),DAY($P32)&" "&CHOOSE(MONTH($P32),"Jan","Feb","Mar","Apr","May","Jun","Jul","Aug","Sep","Oct","Nov","Dec"),"") | J32: =IF(AND($P32>=DATE(2028,7,1),$P32<DATE(2028,10,1)),DAY($P32)&" "&CHOOSE(MONTH($P32),"Jan","Feb","Mar","Apr","May","Jun","Jul","Aug","Sep","Oct","Nov","Dec"),"") | K32: =IF(AND($P32>=DATE(2028,10,1),$P32<DATE(2028,13,1)),DAY($P32)&" "&CHOOSE(MONTH($P32),"Jan","Feb","Mar","Apr","May","Jun","Jul","Aug","Sep","Oct","Nov","Dec"),"") | L32: =IF(AND($P32>=DATE(2029,1,1),$P32<DATE(2029,4,1)),DAY($P32)&" "&CHOOSE(MONTH($P32),"Jan","Feb","Mar","Apr","May","Jun","Jul","Aug","Sep","Oct","Nov","Dec"),"") | M32: =IF(AND($P32>=DATE(2029,4,1),$P32<DATE(2029,7,1)),DAY($P32)&" "&CHOOSE(MONTH($P32),"Jan","Feb","Mar","Apr","May","Jun","Jul","Aug","Sep","Oct","Nov","Dec"),"") | N32: =CHOOSE(MONTH(O32),"Jan","Feb","Mar","Apr","May","Jun","Jul","Aug","Sep","Oct","Nov","Dec")&" "&YEAR(O32)&" → "&DAY(P32)&" "&CHOOSE(MONTH(P32),"Jan","Feb","Mar","Apr","May","Jun","Jul","Aug","Sep","Oct","Nov","Dec")&" "&YEAR(P32)&" ("&((YEAR(P32)-YEAR(O32))*12+MONTH(P32)-MONTH(O32))&" months)" -> Oct 2026 → 1 Mar 2027 (5 months) | O32: =F18 -> 46296 | P32: =G18 -> 46447
B33: =B19 -> Engineering, commissioning & performance test | C33: =IF(AND($P33>=DATE(2026,10,1),$P33<DATE(2026,13,1)),DAY($P33)&" "&CHOOSE(MONTH($P33),"Jan","Feb","Mar","Apr","May","Jun","Jul","Aug","Sep","Oct","Nov","Dec"),"") | D33: =IF(AND($P33>=DATE(2027,1,1),$P33<DATE(2027,4,1)),DAY($P33)&" "&CHOOSE(MONTH($P33),"Jan","Feb","Mar","Apr","May","Jun","Jul","Aug","Sep","Oct","Nov","Dec"),"") | E33: =IF(AND($P33>=DATE(2027,4,1),$P33<DATE(2027,7,1)),DAY($P33)&" "&CHOOSE(MONTH($P33),"Jan","Feb","Mar","Apr","May","Jun","Jul","Aug","Sep","Oct","Nov","Dec"),"") -> 1 Apr | F33: =IF(AND($P33>=DATE(2027,7,1),$P33<DATE(2027,10,1)),DAY($P33)&" "&CHOOSE(MONTH($P33),"Jan","Feb","Mar","Apr","May","Jun","Jul","Aug","Sep","Oct","Nov","Dec"),"") | G33: =IF(AND($P33>=DATE(2027,10,1),$P33<DATE(2027,13,1)),DAY($P33)&" "&CHOOSE(MONTH($P33),"Jan","Feb","Mar","Apr","May","Jun","Jul","Aug","Sep","Oct","Nov","Dec"),"") | H33: =IF(AND($P33>=DATE(2028,1,1),$P33<DATE(2028,4,1)),DAY($P33)&" "&CHOOSE(MONTH($P33),"Jan","Feb","Mar","Apr","May","Jun","Jul","Aug","Sep","Oct","Nov","Dec"),"") | I33: =IF(AND($P33>=DATE(2028,4,1),$P33<DATE(2028,7,1)),DAY($P33)&" "&CHOOSE(MONTH($P33),"Jan","Feb","Mar","Apr","May","Jun","Jul","Aug","Sep","Oct","Nov","Dec"),"") | J33: =IF(AND($P33>=DATE(2028,7,1),$P33<DATE(2028,10,1)),DAY($P33)&" "&CHOOSE(MONTH($P33),"Jan","Feb","Mar","Apr","May","Jun","Jul","Aug","Sep","Oct","Nov","Dec"),"") | K33: =IF(AND($P33>=DATE(2028,10,1),$P33<DATE(2028,13,1)),DAY($P33)&" "&CHOOSE(MONTH($P33),"Jan","Feb","Mar","Apr","May","Jun","Jul","Aug","Sep","Oct","Nov","Dec"),"") | L33: =IF(AND($P33>=DATE(2029,1,1),$P33<DATE(2029,4,1)),DAY($P33)&" "&CHOOSE(MONTH($P33),"Jan","Feb","Mar","Apr","May","Jun","Jul","Aug","Sep","Oct","Nov","Dec"),"") | M33: =IF(AND($P33>=DATE(2029,4,1),$P33<DATE(2029,7,1)),DAY($P33)&" "&CHOOSE(MONTH($P33),"Jan","Feb","Mar","Apr","May","Jun","Jul","Aug","Sep","Oct","Nov","Dec"),"") | N33: =CHOOSE(MONTH(O33),"Jan","Feb","Mar","Apr","May","Jun","Jul","Aug","Sep","Oct","Nov","Dec")&" "&YEAR(O33)&" → "&DAY(P33)&" "&CHOOSE(MONTH(P33),"Jan","Feb","Mar","Apr","May","Jun","Jul","Aug","Sep","Oct","Nov","Dec")&" "&YEAR(P33)&" ("&((YEAR(P33)-YEAR(O33))*12+MONTH(P33)-MONTH(O33))&" months)" -> Oct 2026 → 1 Apr 2027 (6 months) | O33: =F19 -> 46296 | P33: =G19 -> 46478
B34: =B11 -> Fuel receiving, conveyor & automatic feeding | C34: =IF(AND($P34>=DATE(2026,10,1),$P34<DATE(2026,13,1)),DAY($P34)&" "&CHOOSE(MONTH($P34),"Jan","Feb","Mar","Apr","May","Jun","Jul","Aug","Sep","Oct","Nov","Dec"),"") | D34: =IF(AND($P34>=DATE(2027,1,1),$P34<DATE(2027,4,1)),DAY($P34)&" "&CHOOSE(MONTH($P34),"Jan","Feb","Mar","Apr","May","Jun","Jul","Aug","Sep","Oct","Nov","Dec"),"") | E34: =IF(AND($P34>=DATE(2027,4,1),$P34<DATE(2027,7,1)),DAY($P34)&" "&CHOOSE(MONTH($P34),"Jan","Feb","Mar","Apr","May","Jun","Jul","Aug","Sep","Oct","Nov","Dec"),"") -> 1 Apr | F34: =IF(AND($P34>=DATE(2027,7,1),$P34<DATE(2027,10,1)),DAY($P34)&" "&CHOOSE(MONTH($P34),"Jan","Feb","Mar","Apr","May","Jun","Jul","Aug","Sep","Oct","Nov","Dec"),"") | G34: =IF(AND($P34>=DATE(2027,10,1),$P34<DATE(2027,13,1)),DAY($P34)&" "&CHOOSE(MONTH($P34),"Jan","Feb","Mar","Apr","May","Jun","Jul","Aug","Sep","Oct","Nov","Dec"),"") | H34: =IF(AND($P34>=DATE(2028,1,1),$P34<DATE(2028,4,1)),DAY($P34)&" "&CHOOSE(MONTH($P34),"Jan","Feb","Mar","Apr","May","Jun","Jul","Aug","Sep","Oct","Nov","Dec"),"") | I34: =IF(AND($P34>=DATE(2028,4,1),$P34<DATE(2028,7,1)),DAY($P34)&" "&CHOOSE(MONTH($P34),"Jan","Feb","Mar","Apr","May","Jun","Jul","Aug","Sep","Oct","Nov","Dec"),"") | J34: =IF(AND($P34>=DATE(2028,7,1),$P34<DATE(2028,10,1)),DAY($P34)&" "&CHOOSE(MONTH($P34),"Jan","Feb","Mar","Apr","May","Jun","Jul","Aug","Sep","Oct","Nov","Dec"),"") | K34: =IF(AND($P34>=DATE(2028,10,1),$P34<DATE(2028,13,1)),DAY($P34)&" "&CHOOSE(MONTH($P34),"Jan","Feb","Mar","Apr","May","Jun","Jul","Aug","Sep","Oct","Nov","Dec"),"") | L34: =IF(AND($P34>=DATE(2029,1,1),$P34<DATE(2029,4,1)),DAY($P34)&" "&CHOOSE(MONTH($P34),"Jan","Feb","Mar","Apr","May","Jun","Jul","Aug","Sep","Oct","Nov","Dec"),"") | M34: =IF(AND($P34>=DATE(2029,4,1),$P34<DATE(2029,7,1)),DAY($P34)&" "&CHOOSE(MONTH($P34),"Jan","Feb","Mar","Apr","May","Jun","Jul","Aug","Sep","Oct","Nov","Dec"),"") | N34: =CHOOSE(MONTH(O34),"Jan","Feb","Mar","Apr","May","Jun","Jul","Aug","Sep","Oct","Nov","Dec")&" "&YEAR(O34)&" → "&DAY(P34)&" "&CHOOSE(MONTH(P34),"Jan","Feb","Mar","Apr","May","Jun","Jul","Aug","Sep","Oct","Nov","Dec")&" "&YEAR(P34)&" ("&((YEAR(P34)-YEAR(O34))*12+MONTH(P34)-MONTH(O34))&" months)" -> Nov 2026 → 1 Apr 2027 (5 months) | O34: =F11 -> 46327 | P34: =G11 -> 46478
B35: =B17 -> Fire detection, dust control & safety system | C35: =IF(AND($P35>=DATE(2026,10,1),$P35<DATE(2026,13,1)),DAY($P35)&" "&CHOOSE(MONTH($P35),"Jan","Feb","Mar","Apr","May","Jun","Jul","Aug","Sep","Oct","Nov","Dec"),"") | D35: =IF(AND($P35>=DATE(2027,1,1),$P35<DATE(2027,4,1)),DAY($P35)&" "&CHOOSE(MONTH($P35),"Jan","Feb","Mar","Apr","May","Jun","Jul","Aug","Sep","Oct","Nov","Dec"),"") -> 1 Mar | E35: =IF(AND($P35>=DATE(2027,4,1),$P35<DATE(2027,7,1)),DAY($P35)&" "&CHOOSE(MONTH($P35),"Jan","Feb","Mar","Apr","May","Jun","Jul","Aug","Sep","Oct","Nov","Dec"),"") | F35: =IF(AND($P35>=DATE(2027,7,1),$P35<DATE(2027,10,1)),DAY($P35)&" "&CHOOSE(MONTH($P35),"Jan","Feb","Mar","Apr","May","Jun","Jul","Aug","Sep","Oct","Nov","Dec"),"") | G35: =IF(AND($P35>=DATE(2027,10,1),$P35<DATE(2027,13,1)),DAY($P35)&" "&CHOOSE(MONTH($P35),"Jan","Feb","Mar","Apr","May","Jun","Jul","Aug","Sep","Oct","Nov","Dec"),"") | H35: =IF(AND($P35>=DATE(2028,1,1),$P35<DATE(2028,4,1)),DAY($P35)&" "&CHOOSE(MONTH($P35),"Jan","Feb","Mar","Apr","May","Jun","Jul","Aug","Sep","Oct","Nov","Dec"),"") | I35: =IF(AND($P35>=DATE(2028,4,1),$P35<DATE(2028,7,1)),DAY($P35)&" "&CHOOSE(MONTH($P35),"Jan","Feb","Mar","Apr","May","Jun","Jul","Aug","Sep","Oct","Nov","Dec"),"") | J35: =IF(AND($P35>=DATE(2028,7,1),$P35<DATE(2028,10,1)),DAY($P35)&" "&CHOOSE(MONTH($P35),"Jan","Feb","Mar","Apr","May","Jun","Jul","Aug","Sep","Oct","Nov","Dec"),"") | K35: =IF(AND($P35>=DATE(2028,10,1),$P35<DATE(2028,13,1)),DAY($P35)&" "&CHOOSE(MONTH($P35),"Jan","Feb","Mar","Apr","May","Jun","Jul","Aug","Sep","Oct","Nov","Dec"),"") | L35: =IF(AND($P35>=DATE(2029,1,1),$P35<DATE(2029,4,1)),DAY($P35)&" "&CHOOSE(MONTH($P35),"Jan","Feb","Mar","Apr","May","Jun","Jul","Aug","Sep","Oct","Nov","Dec"),"") | M35: =IF(AND($P35>=DATE(2029,4,1),$P35<DATE(2029,7,1)),DAY($P35)&" "&CHOOSE(MONTH($P35),"Jan","Feb","Mar","Apr","May","Jun","Jul","Aug","Sep","Oct","Nov","Dec"),"") | N35: =CHOOSE(MONTH(O35),"Jan","Feb","Mar","Apr","May","Jun","Jul","Aug","Sep","Oct","Nov","Dec")&" "&YEAR(O35)&" → "&DAY(P35)&" "&CHOOSE(MONTH(P35),"Jan","Feb","Mar","Apr","May","Jun","Jul","Aug","Sep","Oct","Nov","Dec")&" "&YEAR(P35)&" ("&((YEAR(P35)-YEAR(O35))*12+MONTH(P35)-MONTH(O35))&" months)" -> Nov 2026 → 1 Mar 2027 (4 months) | O35: =F17 -> 46327 | P35: =G17 -> 46447
B36: =B20 -> ESG certification/traceability setup | C36: =IF(AND($P36>=DATE(2026,10,1),$P36<DATE(2026,13,1)),DAY($P36)&" "&CHOOSE(MONTH($P36),"Jan","Feb","Mar","Apr","May","Jun","Jul","Aug","Sep","Oct","Nov","Dec"),"") | D36: =IF(AND($P36>=DATE(2027,1,1),$P36<DATE(2027,4,1)),DAY($P36)&" "&CHOOSE(MONTH($P36),"Jan","Feb","Mar","Apr","May","Jun","Jul","Aug","Sep","Oct","Nov","Dec"),"") -> 1 Feb | E36: =IF(AND($P36>=DATE(2027,4,1),$P36<DATE(2027,7,1)),DAY($P36)&" "&CHOOSE(MONTH($P36),"Jan","Feb","Mar","Apr","May","Jun","Jul","Aug","Sep","Oct","Nov","Dec"),"") | F36: =IF(AND($P36>=DATE(2027,7,1),$P36<DATE(2027,10,1)),DAY($P36)&" "&CHOOSE(MONTH($P36),"Jan","Feb","Mar","Apr","May","Jun","Jul","Aug","Sep","Oct","Nov","Dec"),"") | G36: =IF(AND($P36>=DATE(2027,10,1),$P36<DATE(2027,13,1)),DAY($P36)&" "&CHOOSE(MONTH($P36),"Jan","Feb","Mar","Apr","May","Jun","Jul","Aug","Sep","Oct","Nov","Dec"),"") | H36: =IF(AND($P36>=DATE(2028,1,1),$P36<DATE(2028,4,1)),DAY($P36)&" "&CHOOSE(MONTH($P36),"Jan","Feb","Mar","Apr","May","Jun","Jul","Aug","Sep","Oct","Nov","Dec"),"") | I36: =IF(AND($P36>=DATE(2028,4,1),$P36<DATE(2028,7,1)),DAY($P36)&" "&CHOOSE(MONTH($P36),"Jan","Feb","Mar","Apr","May","Jun","Jul","Aug","Sep","Oct","Nov","Dec"),"") | J36: =IF(AND($P36>=DATE(2028,7,1),$P36<DATE(2028,10,1)),DAY($P36)&" "&CHOOSE(MONTH($P36),"Jan","Feb","Mar","Apr","May","Jun","Jul","Aug","Sep","Oct","Nov","Dec"),"") | K36: =IF(AND($P36>=DATE(2028,10,1),$P36<DATE(2028,13,1)),DAY($P36)&" "&CHOOSE(MONTH($P36),"Jan","Feb","Mar","Apr","May","Jun","Jul","Aug","Sep","Oct","Nov","Dec"),"") | L36: =IF(AND($P36>=DATE(2029,1,1),$P36<DATE(2029,4,1)),DAY($P36)&" "&CHOOSE(MONTH($P36),"Jan","Feb","Mar","Apr","May","Jun","Jul","Aug","Sep","Oct","Nov","Dec"),"") | M36: =IF(AND($P36>=DATE(2029,4,1),$P36<DATE(2029,7,1)),DAY($P36)&" "&CHOOSE(MONTH($P36),"Jan","Feb","Mar","Apr","May","Jun","Jul","Aug","Sep","Oct","Nov","Dec"),"") | N36: =CHOOSE(MONTH(O36),"Jan","Feb","Mar","Apr","May","Jun","Jul","Aug","Sep","Oct","Nov","Dec")&" "&YEAR(O36)&" → "&DAY(P36)&" "&CHOOSE(MONTH(P36),"Jan","Feb","Mar","Apr","May","Jun","Jul","Aug","Sep","Oct","Nov","Dec")&" "&YEAR(P36)&" ("&((YEAR(P36)-YEAR(O36))*12+MONTH(P36)-MONTH(O36))&" months)" -> Nov 2026 → 1 Feb 2027 (3 months) | O36: =F20 -> 46327 | P36: =G20 -> 46419
B37: =B10 -> Biomass boiler/furnace retrofit package | C37: =IF(AND($P37>=DATE(2026,10,1),$P37<DATE(2026,13,1)),DAY($P37)&" "&CHOOSE(MONTH($P37),"Jan","Feb","Mar","Apr","May","Jun","Jul","Aug","Sep","Oct","Nov","Dec"),"") | D37: =IF(AND($P37>=DATE(2027,1,1),$P37<DATE(2027,4,1)),DAY($P37)&" "&CHOOSE(MONTH($P37),"Jan","Feb","Mar","Apr","May","Jun","Jul","Aug","Sep","Oct","Nov","Dec"),"") | E37: =IF(AND($P37>=DATE(2027,4,1),$P37<DATE(2027,7,1)),DAY($P37)&" "&CHOOSE(MONTH($P37),"Jan","Feb","Mar","Apr","May","Jun","Jul","Aug","Sep","Oct","Nov","Dec"),"") -> 1 Apr | F37: =IF(AND($P37>=DATE(2027,7,1),$P37<DATE(2027,10,1)),DAY($P37)&" "&CHOOSE(MONTH($P37),"Jan","Feb","Mar","Apr","May","Jun","Jul","Aug","Sep","Oct","Nov","Dec"),"") | G37: =IF(AND($P37>=DATE(2027,10,1),$P37<DATE(2027,13,1)),DAY($P37)&" "&CHOOSE(MONTH($P37),"Jan","Feb","Mar","Apr","May","Jun","Jul","Aug","Sep","Oct","Nov","Dec"),"") | H37: =IF(AND($P37>=DATE(2028,1,1),$P37<DATE(2028,4,1)),DAY($P37)&" "&CHOOSE(MONTH($P37),"Jan","Feb","Mar","Apr","May","Jun","Jul","Aug","Sep","Oct","Nov","Dec"),"") | I37: =IF(AND($P37>=DATE(2028,4,1),$P37<DATE(2028,7,1)),DAY($P37)&" "&CHOOSE(MONTH($P37),"Jan","Feb","Mar","Apr","May","Jun","Jul","Aug","Sep","Oct","Nov","Dec"),"") | J37: =IF(AND($P37>=DATE(2028,7,1),$P37<DATE(2028,10,1)),DAY($P37)&" "&CHOOSE(MONTH($P37),"Jan","Feb","Mar","Apr","May","Jun","Jul","Aug","Sep","Oct","Nov","Dec"),"") | K37: =IF(AND($P37>=DATE(2028,10,1),$P37<DATE(2028,13,1)),DAY($P37)&" "&CHOOSE(MONTH($P37),"Jan","Feb","Mar","Apr","May","Jun","Jul","Aug","Sep","Oct","Nov","Dec"),"") | L37: =IF(AND($P37>=DATE(2029,1,1),$P37<DATE(2029,4,1)),DAY($P37)&" "&CHOOSE(MONTH($P37),"Jan","Feb","Mar","Apr","May","Jun","Jul","Aug","Sep","Oct","Nov","Dec"),"") | M37: =IF(AND($P37>=DATE(2029,4,1),$P37<DATE(2029,7,1)),DAY($P37)&" "&CHOOSE(MONTH($P37),"Jan","Feb","Mar","Apr","May","Jun","Jul","Aug","Sep","Oct","Nov","Dec"),"") | N37: =CHOOSE(MONTH(O37),"Jan","Feb","Mar","Apr","May","Jun","Jul","Aug","Sep","Oct","Nov","Dec")&" "&YEAR(O37)&" → "&DAY(P37)&" "&CHOOSE(MONTH(P37),"Jan","Feb","Mar","Apr","May","Jun","Jul","Aug","Sep","Oct","Nov","Dec")&" "&YEAR(P37)&" ("&((YEAR(P37)-YEAR(O37))*12+MONTH(P37)-MONTH(O37))&" months)" -> Jan 2027 → 1 Apr 2027 (3 months) | O37: =F10 -> 46388 | P37: =G10 -> 46478
B38: =B13 -> Ash extraction & handling system | C38: =IF(AND($P38>=DATE(2026,10,1),$P38<DATE(2026,13,1)),DAY($P38)&" "&CHOOSE(MONTH($P38),"Jan","Feb","Mar","Apr","May","Jun","Jul","Aug","Sep","Oct","Nov","Dec"),"") | D38: =IF(AND($P38>=DATE(2027,1,1),$P38<DATE(2027,4,1)),DAY($P38)&" "&CHOOSE(MONTH($P38),"Jan","Feb","Mar","Apr","May","Jun","Jul","Aug","Sep","Oct","Nov","Dec"),"") | E38: =IF(AND($P38>=DATE(2027,4,1),$P38<DATE(2027,7,1)),DAY($P38)&" "&CHOOSE(MONTH($P38),"Jan","Feb","Mar","Apr","May","Jun","Jul","Aug","Sep","Oct","Nov","Dec"),"") -> 1 Apr | F38: =IF(AND($P38>=DATE(2027,7,1),$P38<DATE(2027,10,1)),DAY($P38)&" "&CHOOSE(MONTH($P38),"Jan","Feb","Mar","Apr","May","Jun","Jul","Aug","Sep","Oct","Nov","Dec"),"") | G38: =IF(AND($P38>=DATE(2027,10,1),$P38<DATE(2027,13,1)),DAY($P38)&" "&CHOOSE(MONTH($P38),"Jan","Feb","Mar","Apr","May","Jun","Jul","Aug","Sep","Oct","Nov","Dec"),"") | H38: =IF(AND($P38>=DATE(2028,1,1),$P38<DATE(2028,4,1)),DAY($P38)&" "&CHOOSE(MONTH($P38),"Jan","Feb","Mar","Apr","May","Jun","Jul","Aug","Sep","Oct","Nov","Dec"),"") | I38: =IF(AND($P38>=DATE(2028,4,1),$P38<DATE(2028,7,1)),DAY($P38)&" "&CHOOSE(MONTH($P38),"Jan","Feb","Mar","Apr","May","Jun","Jul","Aug","Sep","Oct","Nov","Dec"),"") | J38: =IF(AND($P38>=DATE(2028,7,1),$P38<DATE(2028,10,1)),DAY($P38)&" "&CHOOSE(MONTH($P38),"Jan","Feb","Mar","Apr","May","Jun","Jul","Aug","Sep","Oct","Nov","Dec"),"") | K38: =IF(AND($P38>=DATE(2028,10,1),$P38<DATE(2028,13,1)),DAY($P38)&" "&CHOOSE(MONTH($P38),"Jan","Feb","Mar","Apr","May","Jun","Jul","Aug","Sep","Oct","Nov","Dec"),"") | L38: =IF(AND($P38>=DATE(2029,1,1),$P38<DATE(2029,4,1)),DAY($P38)&" "&CHOOSE(MONTH($P38),"Jan","Feb","Mar","Apr","May","Jun","Jul","Aug","Sep","Oct","Nov","Dec"),"") | M38: =IF(AND($P38>=DATE(2029,4,1),$P38<DATE(2029,7,1)),DAY($P38)&" "&CHOOSE(MONTH($P38),"Jan","Feb","Mar","Apr","May","Jun","Jul","Aug","Sep","Oct","Nov","Dec"),"") | N38: =CHOOSE(MONTH(O38),"Jan","Feb","Mar","Apr","May","Jun","Jul","Aug","Sep","Oct","Nov","Dec")&" "&YEAR(O38)&" → "&DAY(P38)&" "&CHOOSE(MONTH(P38),"Jan","Feb","Mar","Apr","May","Jun","Jul","Aug","Sep","Oct","Nov","Dec")&" "&YEAR(P38)&" ("&((YEAR(P38)-YEAR(O38))*12+MONTH(P38)-MONTH(O38))&" months)" -> Jan 2027 → 1 Apr 2027 (3 months) | O38: =F13 -> 46388 | P38: =G13 -> 46478
B39: =B14 -> Multi-cyclone + bag filter upgrade | C39: =IF(AND($P39>=DATE(2026,10,1),$P39<DATE(2026,13,1)),DAY($P39)&" "&CHOOSE(MONTH($P39),"Jan","Feb","Mar","Apr","May","Jun","Jul","Aug","Sep","Oct","Nov","Dec"),"") | D39: =IF(AND($P39>=DATE(2027,1,1),$P39<DATE(2027,4,1)),DAY($P39)&" "&CHOOSE(MONTH($P39),"Jan","Feb","Mar","Apr","May","Jun","Jul","Aug","Sep","Oct","Nov","Dec"),"") | E39: =IF(AND($P39>=DATE(2027,4,1),$P39<DATE(2027,7,1)),DAY($P39)&" "&CHOOSE(MONTH($P39),"Jan","Feb","Mar","Apr","May","Jun","Jul","Aug","Sep","Oct","Nov","Dec"),"") -> 1 Apr | F39: =IF(AND($P39>=DATE(2027,7,1),$P39<DATE(2027,10,1)),DAY($P39)&" "&CHOOSE(MONTH($P39),"Jan","Feb","Mar","Apr","May","Jun","Jul","Aug","Sep","Oct","Nov","Dec"),"") | G39: =IF(AND($P39>=DATE(2027,10,1),$P39<DATE(2027,13,1)),DAY($P39)&" "&CHOOSE(MONTH($P39),"Jan","Feb","Mar","Apr","May","Jun","Jul","Aug","Sep","Oct","Nov","Dec"),"") | H39: =IF(AND($P39>=DATE(2028,1,1),$P39<DATE(2028,4,1)),DAY($P39)&" "&CHOOSE(MONTH($P39),"Jan","Feb","Mar","Apr","May","Jun","Jul","Aug","Sep","Oct","Nov","Dec"),"") | I39: =IF(AND($P39>=DATE(2028,4,1),$P39<DATE(2028,7,1)),DAY($P39)&" "&CHOOSE(MONTH($P39),"Jan","Feb","Mar","Apr","May","Jun","Jul","Aug","Sep","Oct","Nov","Dec"),"") | J39: =IF(AND($P39>=DATE(2028,7,1),$P39<DATE(2028,10,1)),DAY($P39)&" "&CHOOSE(MONTH($P39),"Jan","Feb","Mar","Apr","May","Jun","Jul","Aug","Sep","Oct","Nov","Dec"),"") | K39: =IF(AND($P39>=DATE(2028,10,1),$P39<DATE(2028,13,1)),DAY($P39)&" "&CHOOSE(MONTH($P39),"Jan","Feb","Mar","Apr","May","Jun","Jul","Aug","Sep","Oct","Nov","Dec"),"") | L39: =IF(AND($P39>=DATE(2029,1,1),$P39<DATE(2029,4,1)),DAY($P39)&" "&CHOOSE(MONTH($P39),"Jan","Feb","Mar","Apr","May","Jun","Jul","Aug","Sep","Oct","Nov","Dec"),"") | M39: =IF(AND($P39>=DATE(2029,4,1),$P39<DATE(2029,7,1)),DAY($P39)&" "&CHOOSE(MONTH($P39),"Jan","Feb","Mar","Apr","May","Jun","Jul","Aug","Sep","Oct","Nov","Dec"),"") | N39: =CHOOSE(MONTH(O39),"Jan","Feb","Mar","Apr","May","Jun","Jul","Aug","Sep","Oct","Nov","Dec")&" "&YEAR(O39)&" → "&DAY(P39)&" "&CHOOSE(MONTH(P39),"Jan","Feb","Mar","Apr","May","Jun","Jul","Aug","Sep","Oct","Nov","Dec")&" "&YEAR(P39)&" ("&((YEAR(P39)-YEAR(O39))*12+MONTH(P39)-MONTH(O39))&" months)" -> Jan 2027 → 1 Apr 2027 (3 months) | O39: =F14 -> 46388 | P39: =G14 -> 46478
B40: Tranche 2 (2028): efficiency upgrade, 1 item | C40: =IF(AND($P40>=DATE(2026,10,1),$P40<DATE(2026,13,1)),DAY($P40)&" "&CHOOSE(MONTH($P40),"Jan","Feb","Mar","Apr","May","Jun","Jul","Aug","Sep","Oct","Nov","Dec"),"") | D40: =IF(AND($P40>=DATE(2027,1,1),$P40<DATE(2027,4,1)),DAY($P40)&" "&CHOOSE(MONTH($P40),"Jan","Feb","Mar","Apr","May","Jun","Jul","Aug","Sep","Oct","Nov","Dec"),"") | E40: =IF(AND($P40>=DATE(2027,4,1),$P40<DATE(2027,7,1)),DAY($P40)&" "&CHOOSE(MONTH($P40),"Jan","Feb","Mar","Apr","May","Jun","Jul","Aug","Sep","Oct","Nov","Dec"),"") | F40: =IF(AND($P40>=DATE(2027,7,1),$P40<DATE(2027,10,1)),DAY($P40)&" "&CHOOSE(MONTH($P40),"Jan","Feb","Mar","Apr","May","Jun","Jul","Aug","Sep","Oct","Nov","Dec"),"") | G40: =IF(AND($P40>=DATE(2027,10,1),$P40<DATE(2027,13,1)),DAY($P40)&" "&CHOOSE(MONTH($P40),"Jan","Feb","Mar","Apr","May","Jun","Jul","Aug","Sep","Oct","Nov","Dec"),"") | H40: =IF(AND($P40>=DATE(2028,1,1),$P40<DATE(2028,4,1)),DAY($P40)&" "&CHOOSE(MONTH($P40),"Jan","Feb","Mar","Apr","May","Jun","Jul","Aug","Sep","Oct","Nov","Dec"),"") -> 1 Mar | I40: =IF(AND($P40>=DATE(2028,4,1),$P40<DATE(2028,7,1)),DAY($P40)&" "&CHOOSE(MONTH($P40),"Jan","Feb","Mar","Apr","May","Jun","Jul","Aug","Sep","Oct","Nov","Dec"),"") | J40: =IF(AND($P40>=DATE(2028,7,1),$P40<DATE(2028,10,1)),DAY($P40)&" "&CHOOSE(MONTH($P40),"Jan","Feb","Mar","Apr","May","Jun","Jul","Aug","Sep","Oct","Nov","Dec"),"") | K40: =IF(AND($P40>=DATE(2028,10,1),$P40<DATE(2028,13,1)),DAY($P40)&" "&CHOOSE(MONTH($P40),"Jan","Feb","Mar","Apr","May","Jun","Jul","Aug","Sep","Oct","Nov","Dec"),"") | L40: =IF(AND($P40>=DATE(2029,1,1),$P40<DATE(2029,4,1)),DAY($P40)&" "&CHOOSE(MONTH($P40),"Jan","Feb","Mar","Apr","May","Jun","Jul","Aug","Sep","Oct","Nov","Dec"),"") | M40: =IF(AND($P40>=DATE(2029,4,1),$P40<DATE(2029,7,1)),DAY($P40)&" "&CHOOSE(MONTH($P40),"Jan","Feb","Mar","Apr","May","Jun","Jul","Aug","Sep","Oct","Nov","Dec"),"") | N40: =CHOOSE(MONTH(O40),"Jan","Feb","Mar","Apr","May","Jun","Jul","Aug","Sep","Oct","Nov","Dec")&" "&YEAR(O40)&" → "&DAY(P40)&" "&CHOOSE(MONTH(P40),"Jan","Feb","Mar","Apr","May","Jun","Jul","Aug","Sep","Oct","Nov","Dec")&" "&YEAR(P40)&" ("&((YEAR(P40)-YEAR(O40))*12+MONTH(P40)-MONTH(O40))&" months)" -> Oct 2027 → 1 Mar 2028 (5 months) | O40: =MIN(F16) -> 46661 | P40: =MAX(G16) -> 46813
B41: =B16 -> Water treatment & condensate recovery upgrade | C41: =IF(AND($P41>=DATE(2026,10,1),$P41<DATE(2026,13,1)),DAY($P41)&" "&CHOOSE(MONTH($P41),"Jan","Feb","Mar","Apr","May","Jun","Jul","Aug","Sep","Oct","Nov","Dec"),"") | D41: =IF(AND($P41>=DATE(2027,1,1),$P41<DATE(2027,4,1)),DAY($P41)&" "&CHOOSE(MONTH($P41),"Jan","Feb","Mar","Apr","May","Jun","Jul","Aug","Sep","Oct","Nov","Dec"),"") | E41: =IF(AND($P41>=DATE(2027,4,1),$P41<DATE(2027,7,1)),DAY($P41)&" "&CHOOSE(MONTH($P41),"Jan","Feb","Mar","Apr","May","Jun","Jul","Aug","Sep","Oct","Nov","Dec"),"") | F41: =IF(AND($P41>=DATE(2027,7,1),$P41<DATE(2027,10,1)),DAY($P41)&" "&CHOOSE(MONTH($P41),"Jan","Feb","Mar","Apr","May","Jun","Jul","Aug","Sep","Oct","Nov","Dec"),"") | G41: =IF(AND($P41>=DATE(2027,10,1),$P41<DATE(2027,13,1)),DAY($P41)&" "&CHOOSE(MONTH($P41),"Jan","Feb","Mar","Apr","May","Jun","Jul","Aug","Sep","Oct","Nov","Dec"),"") | H41: =IF(AND($P41>=DATE(2028,1,1),$P41<DATE(2028,4,1)),DAY($P41)&" "&CHOOSE(MONTH($P41),"Jan","Feb","Mar","Apr","May","Jun","Jul","Aug","Sep","Oct","Nov","Dec"),"") -> 1 Mar | I41: =IF(AND($P41>=DATE(2028,4,1),$P41<DATE(2028,7,1)),DAY($P41)&" "&CHOOSE(MONTH($P41),"Jan","Feb","Mar","Apr","May","Jun","Jul","Aug","Sep","Oct","Nov","Dec"),"") | J41: =IF(AND($P41>=DATE(2028,7,1),$P41<DATE(2028,10,1)),DAY($P41)&" "&CHOOSE(MONTH($P41),"Jan","Feb","Mar","Apr","May","Jun","Jul","Aug","Sep","Oct","Nov","Dec"),"") | K41: =IF(AND($P41>=DATE(2028,10,1),$P41<DATE(2028,13,1)),DAY($P41)&" "&CHOOSE(MONTH($P41),"Jan","Feb","Mar","Apr","May","Jun","Jul","Aug","Sep","Oct","Nov","Dec"),"") | L41: =IF(AND($P41>=DATE(2029,1,1),$P41<DATE(2029,4,1)),DAY($P41)&" "&CHOOSE(MONTH($P41),"Jan","Feb","Mar","Apr","May","Jun","Jul","Aug","Sep","Oct","Nov","Dec"),"") | M41: =IF(AND($P41>=DATE(2029,4,1),$P41<DATE(2029,7,1)),DAY($P41)&" "&CHOOSE(MONTH($P41),"Jan","Feb","Mar","Apr","May","Jun","Jul","Aug","Sep","Oct","Nov","Dec"),"") | N41: =CHOOSE(MONTH(O41),"Jan","Feb","Mar","Apr","May","Jun","Jul","Aug","Sep","Oct","Nov","Dec")&" "&YEAR(O41)&" → "&DAY(P41)&" "&CHOOSE(MONTH(P41),"Jan","Feb","Mar","Apr","May","Jun","Jul","Aug","Sep","Oct","Nov","Dec")&" "&YEAR(P41)&" ("&((YEAR(P41)-YEAR(O41))*12+MONTH(P41)-MONTH(O41))&" months)" -> Oct 2027 → 1 Mar 2028 (5 months) | O41: =F16 -> 46661 | P41: =G16 -> 46813
B42: Shutdowns, risk window and buyer gates
B43: LNY 2027 shutdown: boiler tie-in | C43: =IF(AND($O43>=DATE(2026,10,1),$O43<DATE(2026,13,1)),CHOOSE(MONTH($O43),"Jan","Feb","Mar","Apr","May","Jun","Jul","Aug","Sep","Oct","Nov","Dec")&IF($P43-$O43>40,"–"&CHOOSE(MONTH($P43),"Jan","Feb","Mar","Apr","May","Jun","Jul","Aug","Sep","Oct","Nov","Dec"),""),"") | D43: =IF(AND($O43>=DATE(2027,1,1),$O43<DATE(2027,4,1)),CHOOSE(MONTH($O43),"Jan","Feb","Mar","Apr","May","Jun","Jul","Aug","Sep","Oct","Nov","Dec")&IF($P43-$O43>40,"–"&CHOOSE(MONTH($P43),"Jan","Feb","Mar","Apr","May","Jun","Jul","Aug","Sep","Oct","Nov","Dec"),""),"") -> Feb | E43: =IF(AND($O43>=DATE(2027,4,1),$O43<DATE(2027,7,1)),CHOOSE(MONTH($O43),"Jan","Feb","Mar","Apr","May","Jun","Jul","Aug","Sep","Oct","Nov","Dec")&IF($P43-$O43>40,"–"&CHOOSE(MONTH($P43),"Jan","Feb","Mar","Apr","May","Jun","Jul","Aug","Sep","Oct","Nov","Dec"),""),"") | F43: =IF(AND($O43>=DATE(2027,7,1),$O43<DATE(2027,10,1)),CHOOSE(MONTH($O43),"Jan","Feb","Mar","Apr","May","Jun","Jul","Aug","Sep","Oct","Nov","Dec")&IF($P43-$O43>40,"–"&CHOOSE(MONTH($P43),"Jan","Feb","Mar","Apr","May","Jun","Jul","Aug","Sep","Oct","Nov","Dec"),""),"") | G43: =IF(AND($O43>=DATE(2027,10,1),$O43<DATE(2027,13,1)),CHOOSE(MONTH($O43),"Jan","Feb","Mar","Apr","May","Jun","Jul","Aug","Sep","Oct","Nov","Dec")&IF($P43-$O43>40,"–"&CHOOSE(MONTH($P43),"Jan","Feb","Mar","Apr","May","Jun","Jul","Aug","Sep","Oct","Nov","Dec"),""),"") | H43: =IF(AND($O43>=DATE(2028,1,1),$O43<DATE(2028,4,1)),CHOOSE(MONTH($O43),"Jan","Feb","Mar","Apr","May","Jun","Jul","Aug","Sep","Oct","Nov","Dec")&IF($P43-$O43>40,"–"&CHOOSE(MONTH($P43),"Jan","Feb","Mar","Apr","May","Jun","Jul","Aug","Sep","Oct","Nov","Dec"),""),"") | I43: =IF(AND($O43>=DATE(2028,4,1),$O43<DATE(2028,7,1)),CHOOSE(MONTH($O43),"Jan","Feb","Mar","Apr","May","Jun","Jul","Aug","Sep","Oct","Nov","Dec")&IF($P43-$O43>40,"–"&CHOOSE(MONTH($P43),"Jan","Feb","Mar","Apr","May","Jun","Jul","Aug","Sep","Oct","Nov","Dec"),""),"") | J43: =IF(AND($O43>=DATE(2028,7,1),$O43<DATE(2028,10,1)),CHOOSE(MONTH($O43),"Jan","Feb","Mar","Apr","May","Jun","Jul","Aug","Sep","Oct","Nov","Dec")&IF($P43-$O43>40,"–"&CHOOSE(MONTH($P43),"Jan","Feb","Mar","Apr","May","Jun","Jul","Aug","Sep","Oct","Nov","Dec"),""),"") | K43: =IF(AND($O43>=DATE(2028,10,1),$O43<DATE(2028,13,1)),CHOOSE(MONTH($O43),"Jan","Feb","Mar","Apr","May","Jun","Jul","Aug","Sep","Oct","Nov","Dec")&IF($P43-$O43>40,"–"&CHOOSE(MONTH($P43),"Jan","Feb","Mar","Apr","May","Jun","Jul","Aug","Sep","Oct","Nov","Dec"),""),"") | L43: =IF(AND($O43>=DATE(2029,1,1),$O43<DATE(2029,4,1)),CHOOSE(MONTH($O43),"Jan","Feb","Mar","Apr","May","Jun","Jul","Aug","Sep","Oct","Nov","Dec")&IF($P43-$O43>40,"–"&CHOOSE(MONTH($P43),"Jan","Feb","Mar","Apr","May","Jun","Jul","Aug","Sep","Oct","Nov","Dec"),""),"") | M43: =IF(AND($O43>=DATE(2029,4,1),$O43<DATE(2029,7,1)),CHOOSE(MONTH($O43),"Jan","Feb","Mar","Apr","May","Jun","Jul","Aug","Sep","Oct","Nov","Dec")&IF($P43-$O43>40,"–"&CHOOSE(MONTH($P43),"Jan","Feb","Mar","Apr","May","Jun","Jul","Aug","Sep","Oct","Nov","Dec"),""),"") | N43: =CHOOSE(MONTH(O43),"Jan","Feb","Mar","Apr","May","Jun","Jul","Aug","Sep","Oct","Nov","Dec")&" "&YEAR(O43)&IF(OR(MONTH(P43)<>MONTH(O43),YEAR(P43)<>YEAR(O43))," to "&CHOOSE(MONTH(P43),"Jan","Feb","Mar","Apr","May","Jun","Jul","Aug","Sep","Oct","Nov","Dec")&" "&YEAR(P43),"")&" (Logistics Cost 2027, Feb-27)" -> Feb 2027 (Logistics Cost 2027, Feb-27) | O43: 46419 | P43: 46419
...

Sheet Task 2_Conversion & Forecast
B1: TASK 2 - SALES CONVERSION 2027-2029 AND VOLUME FORECAST 2030-2031
B2: Requirement 2: a justified conversion rate turns LSC potential orders into realized sales, and 2030-2031 volumes are forecast independently. Realized sales = MIN(risk-adjusted demand after the ESG gate, carbon-allowed capacity).
B4: RISK-ADJUSTED CR 2027 · 2028 · 2029 | C4: REALIZED SALES 2027 | E4: REALIZED SALES 2029 | G4: ORDER GROWTH 2030-2031 | J4: REALIZED SALES 2031 | L4: UNSERVED DEMAND 2030-2031 | N4: PEAK BOILER LOAD
B5: =TEXT(D42,"0.0%")&" · "&TEXT(E42,"0.0%")&" · "&TEXT(F42,"0.0%") -> 91.8% · 90.4% · 88.3% | C5: =D19 -> 5622400 | E5: =F19 -> 8650715 | G5: =G49 -> 0.063333333 | J5: =H19 -> 6125443.2 | L5: =G25+H25 -> 5197517.6 | N5: =MAX(C27:H27) -> 1.72325
B6: CR = (1 + g ESG − |g Traditional|) ÷ (1 + g ESG) | C6: ="+"&TEXT(D19/C19-1,"0%")&" vs 2026" -> +12% vs 2026 | E6: ="+"&TEXT(F19/C19-1,"0%")&" vs 2026 (peak)" -> +72% vs 2026 (peak) | G6: Market component only (shift-share) | J6: ="Bound by "&LOWER(H21) -> Bound by carbon capacity | L6: Declined, not subcontracted | N6: × 2026 heat (2029); no boiler rating in the case
B8: Sales conversion funnel 2026-2031: orders → risk-adjusted demand → ESG gate → carbon capacity → realized sales (pcs)
B9: Metric | C9: 2026 | D9: 2027 | E9: 2028 | F9: 2029 | G9: 2030F | H9: 2031F
B10: Orders and commercial risk
B11: Potential orders (2027-2029) / forecast orders (2030-2031) | C11: =C50 -> 5020000 | D11: =D50 -> 6124400 | E11: =E50 -> 7655500 | F11: =F50 -> 9799040 | G11: =G50 -> 10419646 | H11: =H50 -> 11079557
B12: Conversion rate applied | C12: =C51 -> 1 | D12: =D51 -> 0.91803279 | E12: =E51 -> 0.904 | F12: =F51 -> 0.8828125 | G12: =G51 -> 0.8828125 | H12: =H51 -> 0.8828125
B13: Risk-adjusted demand | C13: =C11*C12 -> 5020000 | D13: =D11*D12 -> 5622400 | E13: =E11*E12 -> 6920572 | F13: =F11*F12 -> 8650715 | G13: =G11*G12 -> 9198593.6 | H13: =H11*H12 -> 9781171.2
B14: ESG gate
B15: TEXIN emission compliance (Task 1) | C15: Baseline | D15: ='Task 1_ESG Roadmap'!D78 -> Compliant | E15: ='Task 1_ESG Roadmap'!E78 -> Compliant | F15: ='Task 1_ESG Roadmap'!F78 -> Compliant | G15: ='Task 1_ESG Roadmap'!G78 -> Compliant | H15: ='Task 1_ESG Roadmap'!H78 -> Compliant
B16: Demand after the ESG gate | C16: =C13 -> 5020000 | D16: =D13 -> 5622400 | E16: =IF(LEFT(D15,9)="Compliant",E13,MIN(E13,D19)) -> 6920572 | F16: =IF(LEFT(E15,9)="Compliant",F13,MIN(F13,E19)) -> 8650715 | G16: =IF(LEFT(F15,9)="Compliant",G13,MIN(G13,F19)) -> 9198593.6 | H16: =IF(LEFT(G15,9)="Compliant",H13,MIN(H13,G19)) -> 9781171.2
B17: Capacity and realized sales
B18: Carbon-allowed capacity | C18: ='Carbon-Allowed Capacity'!C36 -> 5020000 | D18: ='Carbon-Allowed Capacity'!D36 -> 9100807.2 | E18: ='Carbon-Allowed Capacity'!E36 -> 11910584 | F18: ='Carbon-Allowed Capacity'!F36 -> 9358316 | G18: ='Carbon-Allowed Capacity'!G36 -> 7656804 | H18: ='Carbon-Allowed Capacity'!H36 -> 6125443.2
B19: Realized sales volume | C19: ='Sales Forecast & Case 2A KPI'!C21 -> 5020000 | D19: =MIN(D16,D18) -> 5622400 | E19: =MIN(E16,E18) -> 6920572 | F19: =MIN(F16,F18) -> 8650715 | G19: =MIN(G16,G18) -> 7656804 | H19: =MIN(H16,H18) -> 6125443.2
B20: Effective sales conversion rate (realized ÷ orders) | C20: =C19/C11 -> 1 | D20: =D19/D11 -> 0.91803279 | E20: =E19/E11 -> 0.904 | F20: =F19/F11 -> 0.8828125 | G20: =G19/G11 -> 0.73484302 | H20: =H19/H11 -> 0.55285995
B21: Binding constraint | C21: Actual | D21: =IF(D19<D16-0.5,"Carbon capacity",IF(D16<D13-0.5,"ESG gate","Demand")) -> Demand | E21: =IF(E19<E16-0.5,"Carbon capacity",IF(E16<E13-0.5,"ESG gate","Demand")) -> Demand | F21: =IF(F19<F16-0.5,"Carbon capacity",IF(F16<F13-0.5,"ESG gate","Demand")) -> Demand | G21: =IF(G19<G16-0.5,"Carbon capacity",IF(G16<G13-0.5,"ESG gate","Demand")) -> Carbon capacity | H21: =IF(H19<H16-0.5,"Carbon capacity",IF(H16<H13-0.5,"ESG gate","Demand")) -> Carbon capacity
B22: Use of carbon-allowed capacity | C22: =C19/C18 -> 1 | D22: =D19/D18 -> 0.61779135 | E22: =E19/E18 -> 0.58104388 | F22: =F19/F18 -> 0.924388 | G22: =G19/G18 -> 1 | H22: =H19/H18 -> 1
B23: Leakage and load
B24: Orders not converted: commercial risk | C24: =C11-C13 -> 0 | D24: =D11-D13 -> 502000 | E24: =E11-E13 -> 734928 | F24: =F11-F13 -> 1148325 | G24: =G11-G13 -> 1221052.2 | H24: =H11-H13 -> 1298385.6
B25: Orders not served: above carbon capacity | C25: =C16-C19 -> 0 | D25: =D16-D19 -> 0 | E25: =E16-E19 -> 0 | F25: =F16-F19 -> 0 | G25: =G16-G19 -> 1541789.6 | H25: =H16-H19 -> 3655728
B26: Realized volume growth YoY | D26: =D19/C19-1 -> 0.12 | E26: =E19/D19-1 -> 0.23089286 | F26: =F19/E19-1 -> 0.25 | G26: =G19/F19-1 -> -0.11489351 | H26: =H19/G19-1 -> -0.2
B27: Heat demand vs 2026 (×) | C27: =C19/'Sales Forecast & Case 2A KPI'!$C$21 -> 1 | D27: =D19/'Sales Forecast & Case 2A KPI'!$C$21 -> 1.12 | E27: =E19/'Sales Forecast & Case 2A KPI'!$C$21 -> 1.3786 | F27: =F19/'Sales Forecast & Case 2A KPI'!$C$21 -> 1.72325 | G27: =G19/'Sales Forecast & Case 2A KPI'!$C$21 -> 1.5252598 | H27: =H19/'Sales Forecast & Case 2A KPI'!$C$21 -> 1.2202078
